/dcs/large/u2140671/drop-table/Machine-Unlearning-x-Continual-Learning/negGem/net.py:195: UserWarning: The torch.cuda.*DtypeTensor constructors are no longer recommended. It's best to use methods such as torch.tensor(data, dtype=*, device='cuda') to create tensors. (Triggered internally at /pytorch/torch/csrc/tensor/python_tensor.cpp:78.)
  indx = torch.cuda.LongTensor(self.observed_tasks[:-1]) if self.gpu \
/pytorch/aten/src/ATen/native/cuda/Loss.cu:250: nll_loss_forward_reduce_cuda_kernel_2d: block: [0,0,0], thread: [0,0,0] Assertion `t >= 0 && t < n_classes` failed.
/pytorch/aten/src/ATen/native/cuda/Loss.cu:250: nll_loss_forward_reduce_cuda_kernel_2d: block: [0,0,0], thread: [1,0,0] Assertion `t >= 0 && t < n_classes` failed.
/pytorch/aten/src/ATen/native/cuda/Loss.cu:250: nll_loss_forward_reduce_cuda_kernel_2d: block: [0,0,0], thread: [2,0,0] Assertion `t >= 0 && t < n_classes` failed.
/pytorch/aten/src/ATen/native/cuda/Loss.cu:250: nll_loss_forward_reduce_cuda_kernel_2d: block: [0,0,0], thread: [3,0,0] Assertion `t >= 0 && t < n_classes` failed.
/pytorch/aten/src/ATen/native/cuda/Loss.cu:250: nll_loss_forward_reduce_cuda_kernel_2d: block: [0,0,0], thread: [4,0,0] Assertion `t >= 0 && t < n_classes` failed.
/pytorch/aten/src/ATen/native/cuda/Loss.cu:250: nll_loss_forward_reduce_cuda_kernel_2d: block: [0,0,0], thread: [5,0,0] Assertion `t >= 0 && t < n_classes` failed.
/pytorch/aten/src/ATen/native/cuda/Loss.cu:250: nll_loss_forward_reduce_cuda_kernel_2d: block: [0,0,0], thread: [6,0,0] Assertion `t >= 0 && t < n_classes` failed.
/pytorch/aten/src/ATen/native/cuda/Loss.cu:250: nll_loss_forward_reduce_cuda_kernel_2d: block: [0,0,0], thread: [7,0,0] Assertion `t >= 0 && t < n_classes` failed.
multiprocessing.pool.RemoteTraceback: 
"""
Traceback (most recent call last):
  File "/usr/lib64/python3.12/multiprocessing/pool.py", line 125, in worker
    result = (True, func(*args, **kwds))
                    ^^^^^^^^^^^^^^^^^^^
  File "/usr/lib64/python3.12/multiprocessing/pool.py", line 51, in starmapstar
    return list(itertools.starmap(args[0], args[1]))
           ^^^^^^^^^^^^^^^^^^^^^^^^^^^^^^^^^^^^^^^^^
  File "/dcs/large/u2140671/drop-table/Machine-Unlearning-x-Continual-Learning/negGemGradSalun.py", line 397, in single_run
    ALL_TASK_UNLEARN_CONFIDENCES) = run_cifar('GEM', args, device=dev, mem_data_local=mem_data_local, newclasses=SHUFFLEDCLASSES, task_sequence=task_sequence)
                                    ^^^^^^^^^^^^^^^^^^^^^^^^^^^^^^^^^^^^^^^^^^^^^^^^^^^^^^^^^^^^^^^^^^^^^^^^^^^^^^^^^^^^^^^^^^^^^^^^^^^^^^^^^^^^^^^^^^^^^^^^^^
  File "/dcs/large/u2140671/drop-table/Machine-Unlearning-x-Continual-Learning/negGemGradSalun.py", line 300, in run_cifar
    mask = model.unlearn(unlearning_algo, task_to_unlearn, x1=j, x2=j + args.unlearn_batch_size, alpha=args.alpha, mask=mask)
           ^^^^^^^^^^^^^^^^^^^^^^^^^^^^^^^^^^^^^^^^^^^^^^^^^^^^^^^^^^^^^^^^^^^^^^^^^^^^^^^^^^^^^^^^^^^^^^^^^^^^^^^^^^^^^^^^^^
  File "/dcs/large/u2140671/drop-table/Machine-Unlearning-x-Continual-Learning/negGem/net.py", line 268, in unlearn
    loss = -1 * loss
           ~~~^~~~~~
RuntimeError: CUDA error: device-side assert triggered
CUDA kernel errors might be asynchronously reported at some other API call, so the stacktrace below might be incorrect.
For debugging consider passing CUDA_LAUNCH_BLOCKING=1
Compile with `TORCH_USE_CUDA_DSA` to enable device-side assertions.

"""

The above exception was the direct cause of the following exception:

Traceback (most recent call last):
  File "/dcs/large/u2140671/drop-table/Machine-Unlearning-x-Continual-Learning/negGemGradSalun.py", line 462, in <module>
    all_results = pool.starmap(single_run, [(i, SHUFFLEDCLASSES, cmd_args, mem_data_run) for i in range(NUMBER_OF_GPUS)])
                  ^^^^^^^^^^^^^^^^^^^^^^^^^^^^^^^^^^^^^^^^^^^^^^^^^^^^^^^^^^^^^^^^^^^^^^^^^^^^^^^^^^^^^^^^^^^^^^^^^^^^^^^
  File "/usr/lib64/python3.12/multiprocessing/pool.py", line 375, in starmap
    return self._map_async(func, iterable, starmapstar, chunksize).get()
           ^^^^^^^^^^^^^^^^^^^^^^^^^^^^^^^^^^^^^^^^^^^^^^^^^^^^^^^^^^^^^
  File "/usr/lib64/python3.12/multiprocessing/pool.py", line 774, in get
    raise self._value
RuntimeError: CUDA error: device-side assert triggered
CUDA kernel errors might be asynchronously reported at some other API call, so the stacktrace below might be incorrect.
For debugging consider passing CUDA_LAUNCH_BLOCKING=1
Compile with `TORCH_USE_CUDA_DSA` to enable device-side assertions.


real	61m14.623s
user	490m23.046s
sys	26m7.848s
mv: cannot stat './Results*': No such file or directory
